<?xml version="1.0"?>
<robot name="planar_2dof_arm">
  <!-- Minimal placeholder URDF for scaffold testing. Replace with UR5/FR3 for production. -->
  <link name="base_link">
    <visual>
      <geometry><box size="0.2 0.2 0.05"/></geometry>
    </visual>
    <collision>
      <geometry><box size="0.2 0.2 0.05"/></geometry>
    </collision>
    <inertial>
      <mass value="1.0"/>
      <inertia ixx="0.01" ixy="0" ixz="0" iyy="0.01" iyz="0" izz="0.01"/>
    </inertial>
  </link>

  <link name="link1">
    <visual>
      <geometry><cylinder radius="0.03" length="0.3"/></geometry>
    </visual>
    <collision>
      <geometry><cylinder radius="0.03" length="0.3"/></geometry>
    </collision>
    <inertial>
      <mass value="0.5"/>
      <inertia ixx="0.005" ixy="0" ixz="0" iyy="0.005" iyz="0" izz="0.001"/>
    </inertial>
  </link>

  <joint name="joint1" type="revolute">
    <parent link="base_link"/>
    <child link="link1"/>
    <origin xyz="0 0 0.025" rpy="0 0 0"/>
    <axis xyz="0 0 1"/>
    <limit lower="-3.14" upper="3.14" effort="100" velocity="2.0"/>
  </joint>

  <link name="link2">
    <visual>
      <geometry><cylinder radius="0.025" length="0.25"/></geometry>
    </visual>
    <collision>
      <geometry><cylinder radius="0.025" length="0.25"/></geometry>
    </collision>
    <inertial>
      <mass value="0.3"/>
      <inertia ixx="0.003" ixy="0" ixz="0" iyy="0.003" iyz="0" izz="0.001"/>
    </inertial>
  </link>

  <joint name="joint2" type="revolute">
    <parent link="link1"/>
    <child link="link2"/>
    <origin xyz="0 0 0.15" rpy="0 0 0"/>
    <axis xyz="0 0 1"/>
    <limit lower="-2.0" upper="2.0" effort="80" velocity="2.0"/>
  </joint>

  <link name="tool0">
    <inertial>
      <mass value="0.001"/>
      <inertia ixx="0.0001" ixy="0" ixz="0" iyy="0.0001" iyz="0" izz="0.0001"/>
    </inertial>
  </link>
  <joint name="ee_fixed_joint" type="fixed">
    <parent link="link2"/>
    <child link="tool0"/>
    <origin xyz="0 0 0.125" rpy="0 0 0"/>
  </joint>
</robot>
